Workbook

Sheet 消耗品一覧
A1: No. | B1: メーカー | C1: 機種（台帳の型番） | D1: 台数 | E1: 区分 | F1: 色 | G1: 商品名 | H1: 品番・型番 | I1: 品種コード | J1: 印刷可能枚数 | K1: 参考価格 | L1: 価格の別 | M1: リサイクル/互換 | N1: 照合キー | O1: 台帳マスタ | P1: 備考 | Q1: 出典
A2: 1 | B2: Brother | C2: Brother HL-L3230CDW | D2: 1 | E2: トナー | F2: ブラック | G2: トナーカートリッジ TN-293BK | H2: TN-293BK | J2: 3000 | K2: 11770 | L2: 直販価格（税込） | M2: あり | N2: TN-293BK | O2: =IF($N2="","—",IF(COUNTIF(台帳マスタ!$A:$A,$N2)>0,"登録あり","未登録")) | Q2: S15
A3: 2 | B3: Brother | C3: Brother HL-L3230CDW | D3: 1 | E3: トナー | F3: シアン | G3: トナーカートリッジ TN-293C | H3: TN-293C | J3: 1300 | K3: 9900 | L3: 直販価格（税込） | M3: あり | N3: TN-293C | O3: =IF($N3="","—",IF(COUNTIF(台帳マスタ!$A:$A,$N3)>0,"登録あり","未登録")) | Q3: S15
A4: 3 | B4: Brother | C4: Brother HL-L3230CDW | D4: 1 | E4: トナー | F4: マゼンタ | G4: トナーカートリッジ TN-293M | H4: TN-293M | J4: 1300 | K4: 9900 | L4: 直販価格（税込） | M4: あり | N4: TN-293M | O4: =IF($N4="","—",IF(COUNTIF(台帳マスタ!$A:$A,$N4)>0,"登録あり","未登録")) | Q4: S15
A5: 4 | B5: Brother | C5: Brother HL-L3230CDW | D5: 1 | E5: トナー | F5: イエロー | G5: トナーカートリッジ TN-293Y | H5: TN-293Y | J5: 1300 | K5: 9900 | L5: 直販価格（税込） | M5: あり | N5: TN-293Y | O5: =IF($N5="","—",IF(COUNTIF(台帳マスタ!$A:$A,$N5)>0,"登録あり","未登録")) | Q5: S15
A6: 5 | B6: Brother | C6: Brother HL-L3230CDW | D6: 1 | E6: トナー | F6: シアン | G6: 大容量トナーカートリッジ TN-297C | H6: TN-297C | J6: 2300 | L6: 直販価格（税込） | M6: あり | N6: TN-297C | O6: =IF($N6="","—",IF(COUNTIF(台帳マスタ!$A:$A,$N6)>0,"登録あり","未登録")) | P6: 黒の大容量は設定なし | Q6: S14
A7: 6 | B7: Brother | C7: Brother HL-L3230CDW | D7: 1 | E7: トナー | F7: マゼンタ | G7: 大容量トナーカートリッジ TN-297M | H7: TN-297M | J7: 2300 | L7: 直販価格（税込） | M7: あり | N7: TN-297M | O7: =IF($N7="","—",IF(COUNTIF(台帳マスタ!$A:$A,$N7)>0,"登録あり","未登録")) | P7: 黒の大容量は設定なし | Q7: S14
A8: 7 | B8: Brother | C8: Brother HL-L3230CDW | D8: 1 | E8: トナー | F8: イエロー | G8: 大容量トナーカートリッジ TN-297Y | H8: TN-297Y | J8: 2300 | L8: 直販価格（税込） | M8: あり | N8: TN-297Y | O8: =IF($N8="","—",IF(COUNTIF(台帳マスタ!$A:$A,$N8)>0,"登録あり","未登録")) | P8: 黒の大容量は設定なし | Q8: S14
A9: 8 | B9: Brother | C9: Brother HL-L3230CDW | D9: 1 | E9: ドラム | F9: ブラック | G9: ドラムユニット DR-293CL-BK | H9: DR-293CL-BK | J9: 18000 | K9: 6160 | L9: 直販価格（税込） | M9: あり | N9: DR-293CL-BK | O9: =IF($N9="","—",IF(COUNTIF(台帳マスタ!$A:$A,$N9)>0,"登録あり","未登録")) | Q9: S15
A10: 9 | B10: Brother | C10: Brother HL-L3230CDW | D10: 1 | E10: ドラム | F10: カラー | G10: ドラムユニット DR-293CL-CMY（カラー3本） | H10: DR-293CL-CMY | J10: 18000 | K10: 6160 | L10: 直販価格（税込） | M10: あり | N10: DR-293CL-CMY | O10: =IF($N10="","—",IF(COUNTIF(台帳マスタ!$A:$A,$N10)>0,"登録あり","未登録")) | P10: 台帳は色別（-C/-M/-Y）で登録。純正はCMY3本セット | Q10: S15
A11: 10 | B11: Brother | C11: Brother HL-L3230CDW | D11: 1 | E11: ドラム | F11: BK,C,M,Y | G11: ドラムユニット DR-293CL（4本入り） | H11: DR-293CL | J11: 18000 | K11: 16610 | L11: 直販価格（税込） | M11: あり | N11: DR-293CL | O11: =IF($N11="","—",IF(COUNTIF(台帳マスタ!$A:$A,$N11)>0,"登録あり","未登録")) | Q11: S15
A12: 11 | B12: Brother | C12: Brother HL-L3230CDW | D12: 1 | E12: ベルト | F12: — | G12: ベルトユニット BU-223CL | H12: BU-223CL | J12: 50000 | K12: 27500 | L12: 直販価格（税込） | M12: あり | N12: BU-223CL | O12: =IF($N12="","—",IF(COUNTIF(台帳マスタ!$A:$A,$N12)>0,"登録あり","未登録")) | P12: 定期交換部品。台帳マスタに未登録 | Q12: S15
A13: 12 | B13: Brother | C13: Brother HL-L3230CDW | D13: 1 | E13: 廃トナー | F13: — | G13: 廃トナーボックス WT-223CL | H13: WT-223CL | J13: 50000 | K13: 3080 | L13: 直販価格（税込） | M13: あり | N13: WT-223CL | O13: =IF($N13="","—",IF(COUNTIF(台帳マスタ!$A:$A,$N13)>0,"登録あり","未登録")) | P13: 定期交換部品。台帳マスタに未登録 | Q13: S15
A14: 13 | B14: Canon | C14: Canon iR-ADV C3520F | D14: 10 | E14: トナー | F14: ブラック | G14: トナーカートリッジ NPG-67 ブラック | H14: NPG-67 BK | J14: 15000 | K14: 17600 | L14: 実売の参考（税込） | M14: あり | N14: NPG-67BK | O14: =IF($N14="","—",IF(COUNTIF(台帳マスタ!$A:$A,$N14)>0,"登録あり","未登録")) | P14: 純正。価格は販売店により幅がある | Q14: S20
A15: 14 | B15: Canon | C15: Canon iR-ADV C3520F | D15: 10 | E15: トナー | F15: シアン | G15: トナーカートリッジ NPG-67 シアン | H15: NPG-67 C | J15: 9000 | K15: 17600 | L15: 実売の参考（税込） | M15: あり | N15: NPG-67 C | O15: =IF($N15="","—",IF(COUNTIF(台帳マスタ!$A:$A,$N15)>0,"登録あり","未登録")) | P15: 純正。4色セットの例 54,180 円（税別） | Q15: S20
A16: 15 | B16: Canon | C16: Canon iR-ADV C3520F | D16: 10 | E16: トナー | F16: マゼンタ | G16: トナーカートリッジ NPG-67 マゼンタ | H16: NPG-67 M | J16: 9000 | K16: 17600 | L16: 実売の参考（税込） | M16: あり | N16: NPG-67 M | O16: =IF($N16="","—",IF(COUNTIF(台帳マスタ!$A:$A,$N16)>0,"登録あり","未登録")) | P16: 純正。4色セットの例 54,180 円（税別） | Q16: S20
A17: 16 | B17: Canon | C17: Canon iR-ADV C3520F | D17: 10 | E17: トナー | F17: イエロー | G17: トナーカートリッジ NPG-67 イエロー | H17: NPG-67 Y | J17: 9000 | K17: 17600 | L17: 実売の参考（税込） | M17: あり | N17: NPG-67 Y | O17: =IF($N17="","—",IF(COUNTIF(台帳マスタ!$A:$A,$N17)>0,"登録あり","未登録")) | P17: 純正。4色セットの例 54,180 円（税別） | Q17: S20
A18: 17 | B18: Canon | C18: Canon iR-ADV C3520F | D18: 10 | E18: 廃トナー | F18: — | G18: 回収トナー容器 WT-202 | H18: WT-202 | J18: 100000 | K18: 8800 | L18: 実売の参考（税込） | M18: あり | N18: WT-202 | O18: =IF($N18="","—",IF(COUNTIF(台帳マスタ!$A:$A,$N18)>0,"登録あり","未登録")) | P18: 約10万枚で交換。7,700〜9,780 円の実売例 | Q18: S21
A19: 18 | B19: Canon | C19: Canon iR-ADV C3520F | D19: 10 | E19: ドラム | F19: 各色共通 | G19: ドラムユニット NPG-67（海外名 GPR-53） | H19: NPG-67 ドラム | J19: 72600 | L19: 実売の参考（税込） | M19: あり | N19: NPG-67 ドラム | O19: =IF($N19="","—",IF(COUNTIF(台帳マスタ!$A:$A,$N19)>0,"登録あり","未登録")) | P19: 国内は保守契約でのサービス交換が基本。輸入純正が流通 | Q19: S22
A20: 19 | B20: Canon | C20: Canon iR-ADV C3530F | D20: 4 | E20: トナー | F20: ブラック | G20: トナーカートリッジ NPG-67 ブラック | H20: NPG-67 BK | J20: 15000 | K20: 17600 | L20: 実売の参考（税込） | M20: あり | N20: NPG-67BK | O20: =IF($N20="","—",IF(COUNTIF(台帳マスタ!$A:$A,$N20)>0,"登録あり","未登録")) | P20: 純正。価格は販売店により幅がある | Q20: S20
A21: 20 | B21: Canon | C21: Canon iR-ADV C3530F | D21: 4 | E21: トナー | F21: シアン | G21: トナーカートリッジ NPG-67 シアン | H21: NPG-67 C | J21: 9000 | K21: 17600 | L21: 実売の参考（税込） | M21: あり | N21: NPG-67 C | O21: =IF($N21="","—",IF(COUNTIF(台帳マスタ!$A:$A,$N21)>0,"登録あり","未登録")) | P21: 純正。4色セットの例 54,180 円（税別） | Q21: S20
A22: 21 | B22: Canon | C22: Canon iR-ADV C3530F | D22: 4 | E22: トナー | F22: マゼンタ | G22: トナーカートリッジ NPG-67 マゼンタ | H22: NPG-67 M | J22: 9000 | K22: 17600 | L22: 実売の参考（税込） | M22: あり | N22: NPG-67 M | O22: =IF($N22="","—",IF(COUNTIF(台帳マスタ!$A:$A,$N22)>0,"登録あり","未登録")) | P22: 純正。4色セットの例 54,180 円（税別） | Q22: S20
A23: 22 | B23: Canon | C23: Canon iR-ADV C3530F | D23: 4 | E23: トナー | F23: イエロー | G23: トナーカートリッジ NPG-67 イエロー | H23: NPG-67 Y | J23: 9000 | K23: 17600 | L23: 実売の参考（税込） | M23: あり | N23: NPG-67 Y | O23: =IF($N23="","—",IF(COUNTIF(台帳マスタ!$A:$A,$N23)>0,"登録あり","未登録")) | P23: 純正。4色セットの例 54,180 円（税別） | Q23: S20
A24: 23 | B24: Canon | C24: Canon iR-ADV C3530F | D24: 4 | E24: 廃トナー | F24: — | G24: 回収トナー容器 WT-202 | H24: WT-202 | J24: 100000 | K24: 8800 | L24: 実売の参考（税込） | M24: あり | N24: WT-202 | O24: =IF($N24="","—",IF(COUNTIF(台帳マスタ!$A:$A,$N24)>0,"登録あり","未登録")) | P24: 約10万枚で交換。7,700〜9,780 円の実売例 | Q24: S21
A25: 24 | B25: Canon | C25: Canon iR-ADV C3530F | D25: 4 | E25: ドラム | F25: 各色共通 | G25: ドラムユニット NPG-67（海外名 GPR-53） | H25: NPG-67 ドラム | J25: 72600 | L25: 実売の参考（税込） | M25: あり | N25: NPG-67 ドラム | O25: =IF($N25="","—",IF(COUNTIF(台帳マスタ!$A:$A,$N25)>0,"登録あり","未登録")) | P25: 国内は保守契約でのサービス交換が基本。輸入純正が流通 | Q25: S22
A26: 25 | B26: Canon | C26: Canon LBP-6710 | D26: 1 | E26: トナー | F26: ブラック | G26: トナーカートリッジ524 | H26: CRG-524 | I26: 3481B004 | J26: 6000 | L26: 直販価格（税込） | M26: あり | N26: カートリッジ524 | O26: =IF($N26="","—",IF(COUNTIF(台帳マスタ!$A:$A,$N26)>0,"登録あり","未登録")) | P26: ドラム一体型 | Q26: S17
A27: 26 | B27: Canon | C27: Canon LBP-6710 | D27: 1 | E27: トナー | F27: ブラック | G27: トナーカートリッジ524II（大容量） | H27: CRG-524II | I27: 3482B004 | J27: 12500 | K27: 52800 | L27: 直販価格（税込） | M27: あり | N27: CRG-524II | O27: =IF($N27="","—",IF(COUNTIF(台帳マスタ!$A:$A,$N27)>0,"登録あり","未登録")) | P27: ドラム一体型。キヤノンオンラインショップ価格 | Q27: S18
A28: 27 | B28: Canon | C28: Canon LBP-6710 | D28: 1 | E28: ドラム | F28: — | G28: （別売の感光体なし・カートリッジ一体型） | H28: — | L28: — | M28: あり | O28: =IF($N28="","—",IF(COUNTIF(台帳マスタ!$A:$A,$N28)>0,"登録あり","未登録")) | P28: この機種はドラム別売なし | Q28: S17
A29: 28 | B29: EPSON | C29: EPSON PX-M791FT | D29: 3 | E29: インク | F29: ブラック | G29: インクボトル IT08KA（127ml） | H29: IT08KA | J29: 7500 | L29: オープン価格 | M29: あり（互換） | N29: IT08KA | O29: =IF($N29="","—",IF(COUNTIF(台帳マスタ!$A:$A,$N29)>0,"登録あり","未登録")) | Q29: S12
A30: 29 | B30: EPSON | C30: EPSON PX-M791FT | D30: 3 | E30: インク | F30: シアン | G30: インクボトル IT08CA（70ml） | H30: IT08CA | J30: 6000 | L30: オープン価格 | M30: あり（互換） | N30: IT08CA | O30: =IF($N30="","—",IF(COUNTIF(台帳マスタ!$A:$A,$N30)>0,"登録あり","未登録")) | Q30: S12
A31: 30 | B31: EPSON | C31: EPSON PX-M791FT | D31: 3 | E31: インク | F31: マゼンタ | G31: インクボトル IT08MA（70ml） | H31: IT08MA | J31: 6000 | L31: オープン価格 | M31: あり（互換） | N31: IT08MA | O31: =IF($N31="","—",IF(COUNTIF(台帳マスタ!$A:$A,$N31)>0,"登録あり","未登録")) | Q31: S12
A32: 31 | B32: EPSON | C32: EPSON PX-M791FT | D32: 3 | E32: インク | F32: イエロー | G32: インクボトル IT08YA（70ml） | H32: IT08YA | J32: 6000 | L32: オープン価格 | M32: あり（互換） | N32: IT08YA | O32: =IF($N32="","—",IF(COUNTIF(台帳マスタ!$A:$A,$N32)>0,"登録あり","未登録")) | Q32: S12
A33: 32 | B33: EPSON | C33: EPSON PX-M791FT | D33: 3 | E33: メンテナンス | F33: — | G33: メンテナンスボックス PXMB9 | H33: PXMB9 | L33: オープン価格 | M33: あり（互換） | N33: PXMB9 | O33: =IF($N33="","—",IF(COUNTIF(台帳マスタ!$A:$A,$N33)>0,"登録あり","未登録")) | P33: 廃インク吸収体 | Q33: S12
A34: 33 | B34: EPSON | C34: EPSON PX-S381 | D34: 1 | E34: インク | F34: ブラック | G34: インクパック IP04KA（795ml） | H34: IP04KA | J34: 40000 | L34: オープン価格 | M34: あり（互換） | N34: IP04KA | O34: =IF($N34="","—",IF(COUNTIF(台帳マスタ!$A:$A,$N34)>0,"登録あり","未登録")) | P34: PX-M381FL/PX-S381L 用 | Q34: S13
A35: 34 | B35: EPSON | C35: EPSON PX-S381 | D35: 1 | E35: インク | F35: ブラック | G35: インクパック IP03KB（旧型・使用可） | H35: IP03KB | L35: オープン価格 | M35: あり（互換） | N35: IP03KB | O35: =IF($N35="","—",IF(COUNTIF(台帳マスタ!$A:$A,$N35)>0,"登録あり","未登録")) | P35: 旧機種用だが引き続き使用可 | Q35: S13
A36: 35 | B36: EPSON | C36: EPSON PX-S381 | D36: 1 | E36: メンテナンス | F36: — | G36: メンテナンスボックス PXMB8 | H36: PXMB8 | L36: オープン価格 | M36: あり（互換） | N36: PXMB8 | O36: =IF($N36="","—",IF(COUNTIF(台帳マスタ!$A:$A,$N36)>0,"登録あり","未登録")) | Q36: S13
A37: 36 | B37: EPSON | C37: EPSON PX-S381L | D37: 4 | E37: インク | F37: ブラック | G37: インクパック IP04KA（795ml） | H37: IP04KA | J37: 40000 | L37: オープン価格 | M37: あり（互換） | N37: IP04KA | O37: =IF($N37="","—",IF(COUNTIF(台帳マスタ!$A:$A,$N37)>0,"登録あり","未登録")) | P37: PX-M381FL/PX-S381L 用 | Q37: S13
A38: 37 | B38: EPSON | C38: EPSON PX-S381L | D38: 4 | E38: インク | F38: ブラック | G38: インクパック IP03KB（旧型・使用可） | H38: IP03KB | L38: オープン価格 | M38: あり（互換） | N38: IP03KB | O38: =IF($N38="","—",IF(COUNTIF(台帳マスタ!$A:$A,$N38)>0,"登録あり","未登録")) | P38: 旧機種用だが引き続き使用可 | Q38: S13
A39: 38 | B39: EPSON | C39: EPSON PX-S381L | D39: 4 | E39: メンテナンス | F39: — | G39: メンテナンスボックス PXMB8 | H39: PXMB8 | L39: オープン価格 | M39: あり（互換） | N39: PXMB8 | O39: =IF($N39="","—",IF(COUNTIF(台帳マスタ!$A:$A,$N39)>0,"登録あり","未登録")) | Q39: S13
A40: 39 | B40: FUJITSU | C40: FUJITSU XL-9322 | D40: 1 | E40: トナー | F40: ブラック | G40: トナーカートリッジ LB321A（標準） | H40: LB321A | J40: 6000 | K40: 35970 | L40: 実売の参考（税込） | M40: あり | N40: LB321A | O40: =IF($N40="","—",IF(COUNTIF(台帳マスタ!$A:$A,$N40)>0,"登録あり","未登録")) | P40: メーカー希望小売価格 | Q40: S23
...

Sheet 機種サマリー
A1: 機種別サマリー（台帳 62 台 / 22 機種）
A2: 調査日 2026-08-21。台数は端末台帳の登録数。「点数」は本表の消耗品一覧を数えたもの。
A4: メーカー | B4: 機種（台帳の型番） | C4: 台数 | D4: 消耗品点数 | E4: うちトナー/インク | F4: うちドラム | G4: うち廃トナー・回収 | H4: うちメンテ・ベルト | I4: 台帳マスタ未登録 | J4: リサイクル/互換 | K4: リサイクルの状況 | L4: 注意点 | M4: 出典
A5: Brother | B5: Brother HL-L3230CDW | C5: 1 | D5: =COUNTIF(消耗品一覧!$C:$C,$B5) | E5: =COUNTIFS(消耗品一覧!$C:$C,$B5,消耗品一覧!$E:$E,"トナー")+COUNTIFS(消耗品一覧!$C:$C,$B5,消耗品一覧!$E:$E,"インク") | F5: =COUNTIFS(消耗品一覧!$C:$C,$B5,消耗品一覧!$E:$E,"ドラム") | G5: =COUNTIFS(消耗品一覧!$C:$C,$B5,消耗品一覧!$E:$E,"廃トナー") | H5: =COUNTIFS(消耗品一覧!$C:$C,$B5,消耗品一覧!$E:$E,"メンテナンス")+COUNTIFS(消耗品一覧!$C:$C,$B5,消耗品一覧!$E:$E,"ベルト") | I5: =COUNTIFS(消耗品一覧!$C:$C,$B5,消耗品一覧!$O:$O,"未登録") | J5: あり | K5: TN-293/TN-297 の各色に互換・リサイクル品が流通。ドラム DR-293CL も再生品あり | L5: 黒の大容量（TN-297BK）は無く、黒は TN-293BK のみ。ベルトユニット BU-223CL と廃トナーボックス WT-223CL も定期交換部品。 | M5: S34
A6: Canon | B6: Canon LBP-6710 | C6: 1 | D6: =COUNTIF(消耗品一覧!$C:$C,$B6) | E6: =COUNTIFS(消耗品一覧!$C:$C,$B6,消耗品一覧!$E:$E,"トナー")+COUNTIFS(消耗品一覧!$C:$C,$B6,消耗品一覧!$E:$E,"インク") | F6: =COUNTIFS(消耗品一覧!$C:$C,$B6,消耗品一覧!$E:$E,"ドラム") | G6: =COUNTIFS(消耗品一覧!$C:$C,$B6,消耗品一覧!$E:$E,"廃トナー") | H6: =COUNTIFS(消耗品一覧!$C:$C,$B6,消耗品一覧!$E:$E,"メンテナンス")+COUNTIFS(消耗品一覧!$C:$C,$B6,消耗品一覧!$E:$E,"ベルト") | I6: =COUNTIFS(消耗品一覧!$C:$C,$B6,消耗品一覧!$O:$O,"未登録") | J6: あり | K6: トナーカートリッジ524/524II のリサイクル品が流通 | L6: 台帳表記は LBP-6710。実機は Satera LBP6710i。カートリッジはドラム一体型で、感光体の別売なし。 | M6: S32
A7: Canon | B7: Canon iR-ADV C3520F | C7: 10 | D7: =COUNTIF(消耗品一覧!$C:$C,$B7) | E7: =COUNTIFS(消耗品一覧!$C:$C,$B7,消耗品一覧!$E:$E,"トナー")+COUNTIFS(消耗品一覧!$C:$C,$B7,消耗品一覧!$E:$E,"インク") | F7: =COUNTIFS(消耗品一覧!$C:$C,$B7,消耗品一覧!$E:$E,"ドラム") | G7: =COUNTIFS(消耗品一覧!$C:$C,$B7,消耗品一覧!$E:$E,"廃トナー") | H7: =COUNTIFS(消耗品一覧!$C:$C,$B7,消耗品一覧!$E:$E,"メンテナンス")+COUNTIFS(消耗品一覧!$C:$C,$B7,消耗品一覧!$E:$E,"ベルト") | I7: =COUNTIFS(消耗品一覧!$C:$C,$B7,消耗品一覧!$O:$O,"未登録") | J7: あり | K7: NPG-67 のリサイクルトナーが各社にあり（4色）。WT-202 は純正のみが基本 | L7: 複合機。国内では感光体・定着などは保守契約でサービス交換が基本。一般に買えるのはトナー NPG-67 と回収トナー容器 WT-202。 | M7: S22
A8: Canon | B8: Canon iR-ADV C3530F | C8: 4 | D8: =COUNTIF(消耗品一覧!$C:$C,$B8) | E8: =COUNTIFS(消耗品一覧!$C:$C,$B8,消耗品一覧!$E:$E,"トナー")+COUNTIFS(消耗品一覧!$C:$C,$B8,消耗品一覧!$E:$E,"インク") | F8: =COUNTIFS(消耗品一覧!$C:$C,$B8,消耗品一覧!$E:$E,"ドラム") | G8: =COUNTIFS(消耗品一覧!$C:$C,$B8,消耗品一覧!$E:$E,"廃トナー") | H8: =COUNTIFS(消耗品一覧!$C:$C,$B8,消耗品一覧!$E:$E,"メンテナンス")+COUNTIFS(消耗品一覧!$C:$C,$B8,消耗品一覧!$E:$E,"ベルト") | I8: =COUNTIFS(消耗品一覧!$C:$C,$B8,消耗品一覧!$O:$O,"未登録") | J8: あり | K8: NPG-67 のリサイクルトナー（C3520F と共通） | L8: 消耗品は C3520F と共通（NPG-67 / WT-202）。 | M8: S22
A9: EPSON | B9: EPSON PX-M791FT | C9: 3 | D9: =COUNTIF(消耗品一覧!$C:$C,$B9) | E9: =COUNTIFS(消耗品一覧!$C:$C,$B9,消耗品一覧!$E:$E,"トナー")+COUNTIFS(消耗品一覧!$C:$C,$B9,消耗品一覧!$E:$E,"インク") | F9: =COUNTIFS(消耗品一覧!$C:$C,$B9,消耗品一覧!$E:$E,"ドラム") | G9: =COUNTIFS(消耗品一覧!$C:$C,$B9,消耗品一覧!$E:$E,"廃トナー") | H9: =COUNTIFS(消耗品一覧!$C:$C,$B9,消耗品一覧!$E:$E,"メンテナンス")+COUNTIFS(消耗品一覧!$C:$C,$B9,消耗品一覧!$E:$E,"ベルト") | I9: =COUNTIFS(消耗品一覧!$C:$C,$B9,消耗品一覧!$O:$O,"未登録") | J9: あり（互換） | K9: IT08 系の互換インクボトル、PXMB9 の互換メンテナンスボックスあり | L9: エコタンク（インクボトル）。純正はオープン価格で、価格は販売店見積り。 | M9: S28
A10: EPSON | B10: EPSON PX-S381 | C10: 1 | D10: =COUNTIF(消耗品一覧!$C:$C,$B10) | E10: =COUNTIFS(消耗品一覧!$C:$C,$B10,消耗品一覧!$E:$E,"トナー")+COUNTIFS(消耗品一覧!$C:$C,$B10,消耗品一覧!$E:$E,"インク") | F10: =COUNTIFS(消耗品一覧!$C:$C,$B10,消耗品一覧!$E:$E,"ドラム") | G10: =COUNTIFS(消耗品一覧!$C:$C,$B10,消耗品一覧!$E:$E,"廃トナー") | H10: =COUNTIFS(消耗品一覧!$C:$C,$B10,消耗品一覧!$E:$E,"メンテナンス")+COUNTIFS(消耗品一覧!$C:$C,$B10,消耗品一覧!$E:$E,"ベルト") | I10: =COUNTIFS(消耗品一覧!$C:$C,$B10,消耗品一覧!$O:$O,"未登録") | J10: あり（互換） | K10: IP04KA 互換インクパック、PXMB8 互換メンテナンスボックスあり | L10: 台帳の型番は PX-S381L の表記違いと思われる（同一の IP04KA / PXMB8）。台帳を直すか確認したい。 | M10: S30
A11: EPSON | B11: EPSON PX-S381L | C11: 4 | D11: =COUNTIF(消耗品一覧!$C:$C,$B11) | E11: =COUNTIFS(消耗品一覧!$C:$C,$B11,消耗品一覧!$E:$E,"トナー")+COUNTIFS(消耗品一覧!$C:$C,$B11,消耗品一覧!$E:$E,"インク") | F11: =COUNTIFS(消耗品一覧!$C:$C,$B11,消耗品一覧!$E:$E,"ドラム") | G11: =COUNTIFS(消耗品一覧!$C:$C,$B11,消耗品一覧!$E:$E,"廃トナー") | H11: =COUNTIFS(消耗品一覧!$C:$C,$B11,消耗品一覧!$E:$E,"メンテナンス")+COUNTIFS(消耗品一覧!$C:$C,$B11,消耗品一覧!$E:$E,"ベルト") | I11: =COUNTIFS(消耗品一覧!$C:$C,$B11,消耗品一覧!$O:$O,"未登録") | J11: あり（互換） | K11: IP04KA 互換インクパック、PXMB8 互換メンテナンスボックスあり | L11: インクパックは IP04KA。旧 IP03KB も使用可。 | M11: S30
A12: FUJITSU | B12: FUJITSU XL-9322 | C12: 1 | D12: =COUNTIF(消耗品一覧!$C:$C,$B12) | E12: =COUNTIFS(消耗品一覧!$C:$C,$B12,消耗品一覧!$E:$E,"トナー")+COUNTIFS(消耗品一覧!$C:$C,$B12,消耗品一覧!$E:$E,"インク") | F12: =COUNTIFS(消耗品一覧!$C:$C,$B12,消耗品一覧!$E:$E,"ドラム") | G12: =COUNTIFS(消耗品一覧!$C:$C,$B12,消耗品一覧!$E:$E,"廃トナー") | H12: =COUNTIFS(消耗品一覧!$C:$C,$B12,消耗品一覧!$E:$E,"メンテナンス")+COUNTIFS(消耗品一覧!$C:$C,$B12,消耗品一覧!$E:$E,"ベルト") | I12: =COUNTIFS(消耗品一覧!$C:$C,$B12,消耗品一覧!$O:$O,"未登録") | J12: あり | K12: LB321A/LB321M とドラム LB321 のリサイクル品あり（純正の 1/6 程度の例） | L12: 大容量トナーの型番が資料により LB321M / LB321B と分かれる。発注前に実機のラベルで要確認。 | M12: S24
A13: FujiXerox | B13: FujiXerox DocuPrint CP500 d | C13: 1 | D13: =COUNTIF(消耗品一覧!$C:$C,$B13) | E13: =COUNTIFS(消耗品一覧!$C:$C,$B13,消耗品一覧!$E:$E,"トナー")+COUNTIFS(消耗品一覧!$C:$C,$B13,消耗品一覧!$E:$E,"インク") | F13: =COUNTIFS(消耗品一覧!$C:$C,$B13,消耗品一覧!$E:$E,"ドラム") | G13: =COUNTIFS(消耗品一覧!$C:$C,$B13,消耗品一覧!$E:$E,"廃トナー") | H13: =COUNTIFS(消耗品一覧!$C:$C,$B13,消耗品一覧!$E:$E,"メンテナンス")+COUNTIFS(消耗品一覧!$C:$C,$B13,消耗品一覧!$E:$E,"ベルト") | I13: =COUNTIFS(消耗品一覧!$C:$C,$B13,消耗品一覧!$O:$O,"未登録") | J13: あり | K13: CT203057〜60 のリサイクルトナー、CT351149〜52 の再生ドラムが流通 | L13: 現・富士フイルムビジネスイノベーション。標準容量と大容量の 2 系統。ドラムは色ごとに別売。 | M13: S33
A14: HP | B14: HP LaserJet M601 | C14: 1 | D14: =COUNTIF(消耗品一覧!$C:$C,$B14) | E14: =COUNTIFS(消耗品一覧!$C:$C,$B14,消耗品一覧!$E:$E,"トナー")+COUNTIFS(消耗品一覧!$C:$C,$B14,消耗品一覧!$E:$E,"インク") | F14: =COUNTIFS(消耗品一覧!$C:$C,$B14,消耗品一覧!$E:$E,"ドラム") | G14: =COUNTIFS(消耗品一覧!$C:$C,$B14,消耗品一覧!$E:$E,"廃トナー") | H14: =COUNTIFS(消耗品一覧!$C:$C,$B14,消耗品一覧!$E:$E,"メンテナンス")+COUNTIFS(消耗品一覧!$C:$C,$B14,消耗品一覧!$E:$E,"ベルト") | I14: =COUNTIFS(消耗品一覧!$C:$C,$B14,消耗品一覧!$O:$O,"未登録") | J14: あり | K14: CE390A/CE390X は互換・リサイクル品が非常に多い | L14: CE390A（90A）と大容量 CE390X（90X）。定着を含むメンテナンスキット CF064A あり。 | M14: S28
A15: KYOCERA | B15: KYOCERA ECOSYS PA6000x | C15: 3 | D15: =COUNTIF(消耗品一覧!$C:$C,$B15) | E15: =COUNTIFS(消耗品一覧!$C:$C,$B15,消耗品一覧!$E:$E,"トナー")+COUNTIFS(消耗品一覧!$C:$C,$B15,消耗品一覧!$E:$E,"インク") | F15: =COUNTIFS(消耗品一覧!$C:$C,$B15,消耗品一覧!$E:$E,"ドラム") | G15: =COUNTIFS(消耗品一覧!$C:$C,$B15,消耗品一覧!$E:$E,"廃トナー") | H15: =COUNTIFS(消耗品一覧!$C:$C,$B15,消耗品一覧!$E:$E,"メンテナンス")+COUNTIFS(消耗品一覧!$C:$C,$B15,消耗品一覧!$E:$E,"ベルト") | I15: =COUNTIFS(消耗品一覧!$C:$C,$B15,消耗品一覧!$O:$O,"未登録") | J15: あり（リターン方式） | K15: TK-3431 リサイクルは使用済みを返却する方式が主。廃トナーBOX 同梱の商品あり | L15: トナー TK-3431 は 2 本単位の販売。ドラム・廃トナーボックス単体の公式掲載はなく、MK-3381 メンテナンスキットで対応。 | M15: S31
A16: Ricoh | B16: Ricoh IMC3500 | C16: 1 | D16: =COUNTIF(消耗品一覧!$C:$C,$B16) | E16: =COUNTIFS(消耗品一覧!$C:$C,$B16,消耗品一覧!$E:$E,"トナー")+COUNTIFS(消耗品一覧!$C:$C,$B16,消耗品一覧!$E:$E,"インク") | F16: =COUNTIFS(消耗品一覧!$C:$C,$B16,消耗品一覧!$E:$E,"ドラム") | G16: =COUNTIFS(消耗品一覧!$C:$C,$B16,消耗品一覧!$E:$E,"廃トナー") | H16: =COUNTIFS(消耗品一覧!$C:$C,$B16,消耗品一覧!$E:$E,"メンテナンス")+COUNTIFS(消耗品一覧!$C:$C,$B16,消耗品一覧!$E:$E,"ベルト") | I16: =COUNTIFS(消耗品一覧!$C:$C,$B16,消耗品一覧!$O:$O,"未登録") | J16: あり | K16: C3503 各色のリサイクルトナーが流通 | L16: 複合機。保守契約の種別でトナーの品目が変わる（パフォーマンス契約用＝MP P トナー、スポット保守契約用＝MP トナー）。価格は販売担当に確認。 | M16: S27
... A26: Ricoh | B26: Ricoh SP C750 | C26: 1 | D26: =COUNTIF(消耗品一覧!$C:$C,$B26) | E26: =COUNTIFS(消耗品一覧!$C:$C,$B26,消耗品一覧!$E:$E,"トナー")+COUNTIFS(消耗品一覧!$C:$C,$B26,消耗品一覧!$E:$E,"インク") | F26: =COUNTIFS(消耗品一覧!$C:$C,$B26,消耗品一覧!$E:$E,"ドラム") | G26: =COUNTIFS(消耗品一覧!$C:$C,$B26,消耗品一覧!$E:$E,"廃トナー") | H26: =COUNTIFS(消耗品一覧!$C:$C,$B26,消耗品一覧!$E:$E,"メンテナンス")+COUNTIFS(消耗品一覧!$C:$C,$B26,消耗品一覧!$E:$E,"ベルト") | I26: =COUNTIFS(消耗品一覧!$C:$C,$B26,消耗品一覧!$O:$O,"未登録") | J26: あり | K26: C740H 各色のリサイクルトナーあり | L26: SP C751/C750 系。ドラムはカラー用とブラック用で別。 | M26: S28
B27: 合計 | C27: =SUM(C5:C26) | D27: =SUM(D5:D26) | E27: =SUM(E5:E26) | F27: =SUM(F5:F26) | G27: =SUM(G5:G26) | H27: =SUM(H5:H26) | I27: =SUM(I5:I26)

Sheet 台帳マスタ
A1: トナーマスタ（システムに登録済みの品番）
A2: 2026-08-21 時点の GET /api/toners。消耗品一覧の「台帳マスタ」列はこの A 列を COUNTIF で引いている。
A4: トナーID | B4: トナー名 | C4: 色 | D4: 区分 | E4: 登録価格（税別）
A5: KX-FAN190W | B5: KX-FAN190W（KX-FAN190W） | D5: 純正 | E5: 1130
A6: HP728BBK | B6: インクカートリッジ HP728BBK（300ml）（HP 728（総務：ポスター用）） | C6: ブラック | D6: 純正 | E6: 17000
A7: HP728C | B7: インクカートリッジ HP728C（130ml）（HP 728（総務：ポスター用）） | C7: シアン | D7: 純正 | E7: 9100
A8: HP728M | B8: インクカートリッジ HP728M（130ml）（HP 728（総務：ポスター用）） | C8: マゼンタ | D8: 純正 | E8: 9100
A9: HP728Y | B9: インクカートリッジ HP728Y（130ml）（HP 728（総務：ポスター用）） | C9: イエロー | D9: 純正 | E9: 9100
A10: IB09CB | B10: インクカートリッジ IB09CB（PX-S730） | C10: シアン | D10: 純正 | E10: 1100
A11: IB09CL4B | B11: インクカートリッジ IB09CL4B（PX-S730） | C11: 4色パック | D11: 純正 | E11: 7200
A12: IB09KB | B12: インクカートリッジ IB09KB（PX-S730） | C12: ブラック | D12: 純正 | E12: 2400
A13: IB09MB | B13: インクカートリッジ IB09MB（PX-S730） | C13: マゼンタ | D13: 純正 | E13: 1100
A14: IB09YB | B14: インクカートリッジ IB09YB（PX-S730） | C14: イエロー | D14: 純正 | E14: 1100
A15: IB10CA | B15: インクカートリッジ IB10CA（EW-M530F） | C15: シアン | D15: 再生 | E15: 900
A16: IB10CL4A | B16: インクカートリッジ IB10CL4A（EW-M530F） | C16: 4色パック | D16: 再生 | E16: 4900
A17: IB10KA | B17: インクカートリッジ IB10KA（EW-M530F） | C17: ブラック | D17: 再生 | E17: 2500
... A20: IC4CL69 | B20: インクカートリッジ IC4CL69（糖内科（リブレ用）） | C20: 4色パック | D20: 純正 | E20: 2150
A21: ICBK50 | B21: インクカートリッジ ICBK50（リハビリ：コピー用） | C21: ブラック | D21: 純正
A22: ICBK61 | B22: インクカートリッジ ICBK61（PX205） | C22: ブラック | D22: 再生 | E22: 1000
A23: ICBK62 | B23: インクカートリッジ ICBK62（PX205） | C23: ブラック | D23: 再生 | E23: 640
A24: ICBK69L | B24: インクカートリッジ ICBK69L（糖内科（リブレ用）） | C24: ブラック | D24: 純正 | E24: 930
A25: ICBK75 | B25: インクカートリッジ ICBK75（PX-S740） | C25: ブラック | D25: 再生 | E25: 2000
A26: ICBK84 | B26: インクカートリッジ ICBK84（PX-M780F） | C26: ブラック | D26: 再生 | E26: 1880
A27: ICC50 | B27: インクカートリッジ ICC50（リハビリ：コピー用） | C27: シアン | D27: 純正
A28: ICC62 | B28: インクカートリッジ ICC62（PX205） | C28: シアン | D28: 再生 | E28: 550
A29: ICC69 | B29: インクカートリッジ ICC69（糖内科（リブレ用）） | C29: シアン | D29: 純正 | E29: 580
A30: ICC74 | B30: インクカートリッジ ICC74（PX-S740） | C30: シアン | D30: 再生 | E30: 580
A31: ICC84 | B31: インクカートリッジ ICC84（PX-M780F） | C31: シアン | D31: 再生 | E31: 1280
A32: ICLC50 | B32: インクカートリッジ ICLC50（リハビリ：コピー用） | C32: ライトシアン | D32: 純正
A33: ICLM50 | B33: インクカートリッジ ICLM50（リハビリ：コピー用） | C33: ライトマゼンタ | D33: 純正
A34: ICM50 | B34: インクカートリッジ ICM50（リハビリ：コピー用） | C34: マゼンタ | D34: 純正
A35: ICM62 | B35: インクカートリッジ ICM62（PX205） | C35: マゼンタ | D35: 再生 | E35: 550
A36: ICM69 | B36: インクカートリッジ ICM69（糖内科（リブレ用）） | C36: マゼンタ | D36: 純正 | E36: 580
A37: ICM74 | B37: インクカートリッジ ICM74（PX-S740） | C37: マゼンタ | D37: 再生 | E37: 580
A38: ICM84 | B38: インクカートリッジ ICM84（PX-M780F） | C38: マゼンタ | D38: 再生 | E38: 1280
A39: ICY50 | B39: インクカートリッジ ICY50（リハビリ：コピー用） | C39: イエロー | D39: 純正
A40: ICY62 | B40: インクカートリッジ ICY62（PX205） | C40: イエロー | D40: 再生 | E40: 550
A41: ICY69 | B41: インクカートリッジ ICY69（糖内科（リブレ用）） | C41: イエロー | D41: 純正 | E41: 580
A42: ICY74 | B42: インクカートリッジ ICY74（PX-S740） | C42: イエロー | D42: 再生 | E42: 580
A43: ICY84 | B43: インクカートリッジ ICY84（PX-M780F） | C43: イエロー | D43: 再生 | E43: 1280
...

Sheet 出典
A1: 出典一覧
A2: 2026-08-21 に確認。メーカー公式を優先し、公式に記載が無いものは販売店・リサイクル業者のページを使った。
A4: 出典ID | B4: 種別 | C4: 名称 | D4: URL
A5: S01 | B5: メーカー公式 | C5: リコー公式 消耗品など / RICOH P C301SF | D5: https://www.ricoh.co.jp/products/list/ricoh-p-c301sf/supply
A6: S02 | B6: メーカー公式 | C6: リコー公式 消耗品など / RICOH P 501/501M/500/500M | D6: https://www.ricoh.co.jp/products/list/ricoh-p-501-500/supply
A7: S03 | B7: メーカー公式 | C7: リコー公式 消耗品 / RICOH SP 3610 | D7: https://www.ricoh.co.jp/printer/sp/3610/support/supply.html
A8: S04 | B8: メーカー公式 | C8: リコー公式 消耗品など / IPSiO SP 4310/4300 | D8: https://www.ricoh.co.jp/products/list/ipsio-sp-4310-4300/supply
A9: S05 | B9: メーカー公式 | C9: リコー公式 消耗品 / RICOH SP 4510/4500 | D9: https://www.ricoh.co.jp/printer/sp/4510_4500/support/supply.html
A10: S06 | B10: メーカー公式 | C10: リコー公式 消耗品 / IPSiO SP C320 | D10: https://www.ricoh.co.jp/IPSiO/spc/320/support/supply.html
A11: S07 | B11: メーカー公式 | C11: リコー公式 消耗品 / RICOH SP C342/C342M/C341 | D11: https://www.ricoh.co.jp/printer/spc/342_341/support/supply.html
A12: S08 | B12: メーカー公式 | C12: リコー公式 消耗品など / RICOH SP C751/C751M/C750/C750M | D12: https://www.ricoh.co.jp/products/list/ricoh-sp-c751-c750/supply
A13: S09 | B13: メーカー公式 | C13: リコー使用説明書 消耗品一覧 / RICOH IM C6000〜C2000 | D13: https://manuals.ricoh.com/mfp/p_manual/IMC6000JPN/ja/spec/int/consumables.htm
A14: S10 | B14: メーカー公式 | C14: リコー公式 消耗品 / RICOH IM C6000/C5500/C4500/C3500/C3000/C2500 | D14: https://www.ricoh.co.jp/mfp/color/im-C6000-C5500-C4500-C3500-C3000-C2500/support/supply
A15: S11 | B15: メーカー公式 | C15: 富士フイルムBI公式 DocuPrint CP500 d 消耗品と保守サービスの価格 | D15: https://www.fujifilm.com/fb/product/printer/docuprint_cp500d/price.html
... A39: S35 | B39: 販売店・リサイクル業者 | C39: 販売店 アケボノサービス IPSiO SP 4510/SP 4500/SP 3610 対応消耗品 | D39: https://shop.akebono-sv.co.jp/html/page64.html

Sheet 凡例・前提
A1: この表の読み方と前提
A3: 対象 | B3: 端末台帳（printer_assets）62 台を、メーカー＋型番でまとめた 22 機種。台数は 2026-08-21 時点。
A5: 調査日 | B5: 2026-08-21。価格・取り扱いは変わるので、発注前に販売店へ確認すること。
A7: 価格の別 | B7: 「メーカー標準価格（税別）」＝メーカー公式ページの標準価格。「直販価格（税込）」＝メーカー直販サイトの表示価格。「実売の参考（税込）」＝販売店ページの価格例（幅がある）。「オープン価格」＝メーカーが価格を公表しておらず、販売店見積り。
A9: 印刷可能枚数 | B9: 各メーカーの公表値。A4・印字率 5% などの条件付きで、実際の枚数は使い方で変わる。ドラム・メンテナンスキットは交換の目安ページ数。
A11: 区分 | B11: トナー / インク / ドラム（感光体）/ 廃トナー（回収ボトル・容器）/ メンテナンス（キット・ボックス）/ ベルト。
A13: 照合キー | B13: システムのトナーマスタと突き合わせる品番。マスタに同じものがある場合はマスタ側の ID（例 C310H-BK）、無い場合はメーカーの品番をそのまま入れている。色違いで品番が共通のもの（C310 など）は 4 色とも同じ鍵になる。
A15: 台帳マスタ | B15: 「登録あり」＝その品番がトナーマスタにある。「未登録」＝調べた純正品がマスタに無い。「—」＝実在しない行（ドラム別売なし等）で判定していない。※マスタにあることと、機種に紐づいていることは別。紐づけは画面の「機種別トナー」で確認する。
A17: リサイクル/互換 | B17: リサイクル品（使用済みカートリッジを再生）または互換品（他社新品）の流通があるか。個別の商品を推奨するものではなく、選択肢の有無を示す。
A19: 注意（保守契約） | B19: iR-ADV C3520F/C3530F と RICOH IM C3500 は複合機で、感光体・定着などは保守契約でサービス員が交換するのが基本。一般に購入するのはトナーと廃トナー容器が中心になる。
A21: 注意（純正指定） | B21: 各メーカーとも純正品の使用を推奨しており、非純正品による不具合は保証・保守の対象外になる旨を明記している。
A23: 注意（販売終了） | B23: Ricoh の SP 系・P C301SF・IPSiO SP 4310、DocuPrint CP500 d、HL-L3230CDW などは本体が販売終了品。消耗品の供給期限があるため、在庫の持ち方は別途検討が必要。
A25: 空欄の意味 | B25: 印刷可能枚数・価格の空欄は「公表されていない／今回の調査で確認できなかった」。0 ではない。
